Workbook

Sheet Lương 0624_ để check
AO1: 0.105 | AP1: 0.215 | AR1: 4400000
AR2: 11000000 | BA2: =BA9+BA18+BA21+BA31+BA33 -> #VALUE! | BB2: 47000 | BJ2: Chốt | BM2: 13358652
A3: BẢNG LƯƠNG THÁNG 06/2024 | BJ3: Tổng lương thực nhận | BK3: =SUM(AZ9:AZ33) -> #VALUE! | BM3: 472375765
A4: THÔNG TIN NHÂN VIÊN | H4: TỔNG LƯƠNG GROSS | U4: NGÀY CÔNG TÍNH LƯƠNG | AA4: LƯƠNG THEO NGÀY CÔNG | AF4: CÁC KHOẢN THU NHẬP/GIẢM TRỪ KHÁC | AM4: TỔNG THU NHẬP (32=17+22+25) | AN4: BHXH | AQ4: THUẾ TNCN | AW4: THỰC LĨNH | BA4: TỔNG CHI PHÍ LƯƠNG, THƯỞNG | BB4: Note | BJ4: Tổng chi phí lương, thưởng | BK4: =SUM(BA9:BA33) -> #VALUE!
A5: STT | B5: Mã nhân viên | C5: Họ và tên | D5: Email | E5: Vị trí | F5: Thuế | G5: Code | H5: CTV/thực tập | J5: Nhân viên thử việc | M5: Tổng lương gross | N5: Nhân viên chính thức | U5: Tổng ngày công | V5: Ngày công chuẩn | W5: Ngày công CTV / thực tập | X5: Ngày công thử việc | Y5: Ngày công chính thức | Z5: Ngày công trước khi điều chỉnh lương | AA5: Tổng lương theo ngày công (16= 17+18+19 | AB5: Lương ngày công CTV / thực tập | AC5: Lương ngày công thử việc | AD5: Lương ngày công chính thức | AE5: Lương ngày công CTV / thực tập trước ĐC | AF5: Các khoản tăng/giảm khác (23=24+25+26+27+28+29+30) | AG5: Các khoản bổ sung khác | AH5: Thanh toán phép tồn | AI5: Hỗ trợ nhà ở | AJ5: Thưởng (Doanh số, Hiệu quả, Thành tích đặc biệt,…) | AK5: Thưởng các dịp lễ | AL5: Bonus/Lương tháng 13 | AN5: Mức lương đóng BHXH | AO5: BHXH NV đóng (10.5%* lương cơ bản) | AP5: BHXH Công ty đóng (21.5%* lương cơ bản) | AQ5: Tổng số người phụ thuộc | AR5: Giảm trừ bản thân và giảm trừ NPT | AS5: Thu nhập chịu thuế | AT5: Thu nhập tính thuế | AU5: Thuế TNCN | AW5: Tổng thu nhập sau thuế | AX5: Các khoản trừ ngoài lương (-) ( tạm ứng lương, truy thu thuế TNCN…) | AY5: Các khoản cộng ngoài lương (+) ( truy lĩnh thuế TNCN, bù trừ lương tháng ....) | AZ5: LƯƠNG THỰC NHẬN (44=41-42+43 | BI5: Cần chú ý
H6: Tổng lương CTV / thực tập | I6: Tổng lương CTV / thực tập trước ĐC | J6: Tổng lương thử việc (2=3+4) | K6: Lương thử việc | L6: Hỗ trợ ăn trưa | N6: Tổng lương | O6: Lương cơ bản | P6: Thưởng hiệu suất | Q6: Xăng xe | R6: Hỗ trợ Đồng phục | S6: Hỗ trợ điện thoại | T6: Hỗ trợ ăn trưa | AU6: Thuế 10% | AV6: Thuế lũy tiến | BD6: Check thuế | BE6: Check BHXH | BF6: Check loại hình NV | BG6: Check công | BH6: Check tình trạng HĐ | BJ6: Chênh tổng chi phí | BK6: Chênh thực nhận
H7: VND | J7: VND | K7: VND | L7: VND | M7: VND | N7: VND | O7: VND | P7: VND | R7: VND | S7: VND | T7: VND | U7: Ngày | W7: Ngày | X7: Ngày | Y7: Ngày | AA7: VND | AB7: VND | AC7: VND | AD7: VND | AF7: VND | AG7: VND | AH7: VND | AI7: VND | AJ7: VND | AL7: VND | AM7: VND | AN7: VND | AO7: VND | AP7: VND | AQ7: Người | AR7: VNĐ | AS7: VNĐ | AT7: VNĐ | AV7: VNĐ | AW7: VNĐ | AX7: VNĐ | AY7: VNĐ | AZ7: VNĐ | BA7: VNĐ
H8: 1 | J8: 2 | K8: 3 | L8: 4 | M8: 5 | N8: 5 | O8: 6 | P8: 7 | R8: 8 | S8: 9 | T8: 10 | U8: 11 | V8: 12 | W8: 13 | X8: 14 | Y8: 15 | AA8: 16 | AB8: 17 | AC8: 18 | AD8: 19 | AF8: 23 | AG8: 24 | AH8: 26 | AI8: 27 | AJ8: 28 | AK8: 29 | AL8: 30 | AM8: 31 | AN8: 32 | AO8: 33 | AP8: 34 | AQ8: 35 | AR8: 36 | AS8: 37 | AT8: 38 | AU8: 39 | AV8: 40 | AW8: 41 | AX8: 42 | AY8: 43 | AZ8: 44 | BA8: 47
A9: 1 | B9: BSM00001 | C9: Nguyễn Châu Hy | D9: hync.zenme@gmail.com | E9: Trợ lý Giám đốc | G9: ON | M9: =26950794+H37 -> 27950794 | N9: =M9 -> 27950794 | O9: 5100000 | P9: =N9-(O9+Q9+R9+S9+T9) -> 20970794 | Q9: 250000 | R9: 400000 | S9: 500000 | T9: 730000 | U9: =SUM(W9:Y9) -> 10 | V9: 20 | Y9: 10 | AA9: =SUM(AB9:AD9) -> 13975397 | AB9: =ROUND($H9/V9*W9,0) -> 0 | AC9: =ROUND(J9/V9*X9,0) -> 0 | AD9: =ROUND($N9/V9*Y9,0) -> 13975397 | AF9: =SUM(AG9:AL9) -> 0 | AM9: =AA9+AF9 -> 13975397 | AN9: 5100000 | AO9: =$AN9*$AO$1 -> 535500 | AP9: =$AN9*$AP$1 -> 1096500 | AR9: =IF($F9=10%,0,(AQ9*$AR$1+$AR$2)) -> 11000000 | AS9: =AM9-(R9+S9+T9)/V9*U9 -> 13160397 | AT9: =ROUND(IF((AS9-AR9-AO9)<0,0,(AS9-AR9-AO9)),0) -> 1624897 | AU9: =ROUND(IF($F9=10%,ROUND(AS9*10%,0),0),0) -> 0 | AV9: =ROUND(IF(AU9>0,0,IF(AT9<5000000,AT9*5%,IF(AT9<10000000,250000+(AT9-5000000)*10%,IF(AT9<18000000,750000+(AT9-10000000)*15%,IF(AT9<32000000,1950000+(AT9-18000000)*20%,IF(AT9<52000000,4750000+(AT9-32000000)*25%,IF(AT9<80000000,9750000+(AT9-52000000)*30%,IF(AT9<400000000,18150000+(AT9-80000000)*35%,0)))))))),0) -> 81245 | AW9: =AM9-AO9-AV9-AU9 -> 13358652 | AZ9: =ROUND(AW9-AX9+AY9,0) -> 13358652 | BA9: =AM9+AP9 -> 15071897 | BB9: Ngày công T6= 1/2 ngày công T5, T6 thuế TNCN tăng vì gộp ttoans trong hết | BC9: #N/A | BD9: =IF(AND(AN9>0,AU9>0),"check","") | BE9: =IF(AND($F9<>10%,$AN9=0),"check","") | BF9: =IF(AND(#REF!="CT",F9=10%,AN9<>0),"check","") -> #REF! | BG9: =IF(AND(F9=10%,Y9>12),"check","") | BH9: =IF(AND(F9=10%,#REF!="CT"),"check","") -> #REF! | BJ9: =BA9-#REF! -> #REF! | BK9: =AZ9-#REF! -> #REF! | BL9: =C9=#REF! -> #REF! | BM9: Thực Lĩnh tháng 6/2024 | BN9: =SUM(AZ9:AZ33) -> #VALUE!
A10: 2 | B10: BSM00002 | C10: Bùi Văn Điệp | D10: chuaco@congty.cty | E10: Lập trình viên | G10: ON | M10: =26298235+H36+2000000 -> 51798235 | N10: =M10 -> 51798235 | O10: 9000000 | P10: =N10-(O10+Q10+R10+S10+T10) -> 40168235 | Q10: 500000 | R10: 400000 | S10: 1000000 | T10: 730000 | U10: =SUM(W10:Y10) -> 20 | V10: 20 | Y10: 20 | AA10: =SUM(AB10:AD10) -> 51798235 | AB10: =ROUND($H10/V10*W10,0) -> 0 | AC10: =ROUND(J10/V10*X10,0) -> 0 | AD10: =ROUND($N10/V10*Y10,0) -> 51798235 | AF10: =SUM(AG10:AL10) -> 0 | AM10: =AA10+AF10 -> 51798235 | AN10: 6000000 | AO10: =$AN10*$AO$1 -> 630000 | AP10: =$AN10*$AP$1 -> 1290000 | AQ10: 3 | AR10: =IF($F10=10%,0,(AQ10*$AR$1+$AR$2)) -> 24200000 | AS10: =AM10-R10-S10-T10 -> 49668235 | AT10: =ROUND(IF((AS10-AR10-AO10)<0,0,(AS10-AR10-AO10)),0) -> 24838235 | AU10: =ROUND(IF($F10=10%,ROUND(AS10*10%,0),0),0) -> 0 | AV10: =ROUND(IF(AU10>0,0,IF(AT10<5000000,AT10*5%,IF(AT10<10000000,250000+(AT10-5000000)*10%,IF(AT10<18000000,750000+(AT10-10000000)*15%,IF(AT10<32000000,1950000+(AT10-18000000)*20%,IF(AT10<52000000,4750000+(AT10-32000000)*25%,IF(AT10<80000000,9750000+(AT10-52000000)*30%,IF(AT10<400000000,18150000+(AT10-80000000)*35%,0)))))))),0) -> 3317647 | AW10: =AM10-AO10-AV10-AU10 -> 47850588 | AZ10: =ROUND(AW10-AX10+AY10,0) -> 47850588 | BA10: =AM10+AP10 -> 53088235 | BB10: bảng lương T6 gộp 1 dòng, Bảng lương T5 tách 2 dòng, T6 thuế TNCN tăng vì gộp ttoans trong hết | BI10: Thêm 2 tr đảm bảo thu nhập net 48 | BJ10: =BA10-#REF! -> #REF! | BK10: =AZ10-#REF! -> #REF! | BL10: =C10=#REF! -> #REF! | BM10: Tổng chi phí lương thưởng tháng 6/2024 | BN10: =SUM(BA9:BA33) -> #VALUE!
A11: 3 | B11: BSM00003 | C11: Nguyễn Ngọc Anh | D11: ssinz7.zenme@gmail.com | E11: Lập trình viên | G11: ON | M11: =36728000+H38 -> 40728000 | N11: =M11 -> 40728000 | O11: 5100000 | P11: =N11-(O11+Q11+R11+S11+T11) -> 33248000 | Q11: 250000 | R11: 400000 | S11: 1000000 | T11: 730000 | U11: =SUM(W11:Y11) -> 20 | V11: 20 | Y11: 20 | AA11: =SUM(AB11:AD11) -> 40728000 | AB11: =ROUND($H11/V11*W11,0) -> 0 | AC11: =ROUND(J11/V11*X11,0) -> 0 | AD11: =ROUND($N11/V11*Y11,0) -> 40728000 | AF11: =SUM(AG11:AL11) -> 0 | AM11: =AA11+AF11 -> 40728000 | AN11: 5100000 | AO11: =$AN11*$AO$1 -> 535500 | AP11: =$AN11*$AP$1 -> 1096500 | AR11: =IF($F11=10%,0,(AQ11*$AR$1+$AR$2)) -> 11000000 | AS11: =AM11-R11-S11-T11 -> 38598000 | AT11: =ROUND(IF((AS11-AR11-AO11)<0,0,(AS11-AR11-AO11)),0) -> 27062500 | AU11: =ROUND(IF($F11=10%,ROUND(AS11*10%,0),0),0) -> 0 | AV11: =ROUND(IF(AU11>0,0,IF(AT11<5000000,AT11*5%,IF(AT11<10000000,250000+(AT11-5000000)*10%,IF(AT11<18000000,750000+(AT11-10000000)*15%,IF(AT11<32000000,1950000+(AT11-18000000)*20%,IF(AT11<52000000,4750000+(AT11-32000000)*25%,IF(AT11<80000000,9750000+(AT11-52000000)*30%,IF(AT11<400000000,18150000+(AT11-80000000)*35%,0)))))))),0) -> 3762500 | AW11: =AM11-AO11-AV11-AU11 -> 36430000 | AZ11: =ROUND(AW11-AX11+AY11,0) -> 36430000 | BA11: =AM11+AP11 -> 41824500 | BB11: bảng lương T6 gộp 1 dòng, Bảng lương T5 tách 2 dòng, T6 thuế TNCN tăng vì gộp ttoans trong hết | BJ11: =BA11-#REF! -> #REF! | BK11: =AZ11-#REF! -> #REF! | BL11: =C11=#REF! -> #REF! | BM11: Total | BN11: =SUM(BN9:BN10) -> #VALUE!
A12: 4 | B12: BSM00005 | C12: Phan Thanh Tùng | D12: tungpt.zenme@gmail.com | E12: Lập trình viên | G12: ON | M12: =31000000+H39 -> 32000000 | N12: =M12 -> 32000000 | O12: 5100000 | P12: =N12-(O12+Q12+R12+S12+T12) -> 25020000 | Q12: 250000 | R12: 400000 | S12: 500000 | T12: 730000 | U12: =SUM(W12:Y12) -> 20 | V12: 20 | Y12: 20 | AA12: =SUM(AB12:AD12) -> 32000000 | AB12: =ROUND($H12/V12*W12,0) -> 0 | AC12: =ROUND(J12/V12*X12,0) -> 0 | AD12: =ROUND($N12/V12*Y12,0) -> 32000000 | AF12: =SUM(AG12:AL12) -> 0 | AM12: =AA12+AF12 -> 32000000 | AN12: 5100000 | AO12: =$AN12*$AO$1 -> 535500 | AP12: =$AN12*$AP$1 -> 1096500 | AR12: =IF($F12=10%,0,(AQ12*$AR$1+$AR$2)) -> 11000000 | AS12: =AM12-R12-S12-T12 -> 30370000 | AT12: =ROUND(IF((AS12-AR12-AO12)<0,0,(AS12-AR12-AO12)),0) -> 18834500 | AU12: =ROUND(IF($F12=10%,ROUND(AS12*10%,0),0),0) -> 0 | AV12: =ROUND(IF(AU12>0,0,IF(AT12<5000000,AT12*5%,IF(AT12<10000000,250000+(AT12-5000000)*10%,IF(AT12<18000000,750000+(AT12-10000000)*15%,IF(AT12<32000000,1950000+(AT12-18000000)*20%,IF(AT12<52000000,4750000+(AT12-32000000)*25%,IF(AT12<80000000,9750000+(AT12-52000000)*30%,IF(AT12<400000000,18150000+(AT12-80000000)*35%,0)))))))),0) -> 2116900 | AW12: =AM12-AO12-AV12-AU12 -> 29347600 | AZ12: =ROUND(AW12-AX12+AY12,0) -> 29347600 | BA12: =AM12+AP12 -> 33096500 | BJ12: =BA12-#REF! -> #REF! | BK12: =AZ12-#REF! -> #REF! | BL12: =C12=#REF! -> #REF!
A13: 5 | B13: BSM00006 | C13: Nguyễn Thị Hà | D13: hant.zenme@gmail.com | E13: Marketing | G13: ON | M13: =18000000+H40 -> 19000000 | N13: =M13 -> 19000000 | O13: 5100000 | P13: =N13-(O13+Q13+R13+S13+T13) -> 12020000 | Q13: 250000 | R13: 400000 | S13: 500000 | T13: 730000 | U13: =SUM(W13:Y13) -> 20 | V13: 20 | Y13: 20 | AA13: =SUM(AB13:AD13) -> 19000000 | AB13: =ROUND($H13/V13*W13,0) -> 0 | AC13: =ROUND(J13/V13*X13,0) -> 0 | AD13: =ROUND($N13/V13*Y13,0) -> 19000000 | AF13: =SUM(AG13:AL13) -> 0 | AM13: =AA13+AF13 -> 19000000 | AN13: 5100000 | AO13: =$AN13*$AO$1 -> 535500 | AP13: =$AN13*$AP$1 -> 1096500 | AR13: =IF($F13=10%,0,(AQ13*$AR$1+$AR$2)) -> 11000000 | AS13: =AM13-R13-S13-T13 -> 17370000 | AT13: =ROUND(IF((AS13-AR13-AO13)<0,0,(AS13-AR13-AO13)),0) -> 5834500 | AU13: =ROUND(IF($F13=10%,ROUND(AS13*10%,0),0),0) -> 0 | AV13: =ROUND(IF(AU13>0,0,IF(AT13<5000000,AT13*5%,IF(AT13<10000000,250000+(AT13-5000000)*10%,IF(AT13<18000000,750000+(AT13-10000000)*15%,IF(AT13<32000000,1950000+(AT13-18000000)*20%,IF(AT13<52000000,4750000+(AT13-32000000)*25%,IF(AT13<80000000,9750000+(AT13-52000000)*30%,IF(AT13<400000000,18150000+(AT13-80000000)*35%,0)))))))),0) -> 333450 | AW13: =AM13-AO13-AV13-AU13 -> 18131050 | AZ13: =ROUND(AW13-AX13+AY13,0) -> 18131050 | BA13: =AM13+AP13 -> 20096500 | BJ13: =BA13-#REF! -> #REF! | BK13: =AZ13-#REF! -> #REF! | BL13: =C13=#REF! -> #REF!
A14: 6 | B14: BSM00007 | C14: Nguyễn Ngọc Lê | D14: le.n.nguyen0192@gmail.com | E14: Lập trình viên | G14: ON | M14: =26215500+H41 -> 29715500 | N14: =M14 -> 29715500 | O14: 5100000 | P14: =N14-(O14+Q14+R14+S14+T14) -> 22735500 | Q14: 250000 | R14: 400000 | S14: 500000 | T14: 730000 | U14: =SUM(W14:Y14) -> 20 | V14: 20 | Y14: 20 | AA14: =SUM(AB14:AD14) -> 29715500 | AB14: =ROUND($H14/V14*W14,0) -> 0 | AC14: =ROUND(J14/V14*X14,0) -> 0 | AD14: =ROUND($N14/V14*Y14,0) -> 29715500 | AF14: =SUM(AG14:AL14) -> 0 | AM14: =AA14+AF14 -> 29715500 | AN14: 5100000 | AO14: =$AN14*$AO$1 -> 535500 | AP14: =$AN14*$AP$1 -> 1096500 | AQ14: 1 | AR14: =IF($F14=10%,0,(AQ14*$AR$1+$AR$2)) -> 15400000 | AS14: =AM14-R14-S14-T14 -> 28085500 | AT14: =ROUND(IF((AS14-AR14-AO14)<0,0,(AS14-AR14-AO14)),0) -> 12150000 | AU14: =ROUND(IF($F14=10%,ROUND(AS14*10%,0),0),0) -> 0 | AV14: =ROUND(IF(AU14>0,0,IF(AT14<5000000,AT14*5%,IF(AT14<10000000,250000+(AT14-5000000)*10%,IF(AT14<18000000,750000+(AT14-10000000)*15%,IF(AT14<32000000,1950000+(AT14-18000000)*20%,IF(AT14<52000000,4750000+(AT14-32000000)*25%,IF(AT14<80000000,9750000+(AT14-52000000)*30%,IF(AT14<400000000,18150000+(AT14-80000000)*35%,0)))))))),0) -> 1072500 | AW14: =AM14-AO14-AV14-AU14 -> 28107500 | AZ14: =ROUND(AW14-AX14+AY14,0) -> 28107500 | BA14: =AM14+AP14 -> 30812000 | BJ14: =BA14-#REF! -> #REF! | BK14: =AZ14-#REF! -> #REF! | BL14: =C14=#REF! -> #REF!
A15: 7 | B15: BSM00008 | C15: Nguyễn Hồng Nhung | D15: nhungnh.zenme@gmail.com | E15: Trợ lý kinh doanh | G15: ON | M15: =18000000+H42 -> 21000000 | N15: =M15 -> 21000000 | O15: 5100000 | P15: =N15-(O15+Q15+R15+S15+T15) -> 14020000 | Q15: 250000 | R15: 400000 | S15: 500000 | T15: 730000 | U15: =SUM(W15:Y15) -> 20 | V15: 20 | Y15: 20 | AA15: =SUM(AB15:AD15) -> 21000000 | AB15: =ROUND($H15/V15*W15,0) -> 0 | AC15: =ROUND(J15/V15*X15,0) -> 0 | AD15: =ROUND($N15/V15*Y15,0) -> 21000000 | AF15: =SUM(AG15:AL15) -> 0 | AM15: =AA15+AF15 -> 21000000 | AN15: 5100000 | AO15: =$AN15*$AO$1 -> 535500 | AP15: =$AN15*$AP$1 -> 1096500 | AR15: =IF($F15=10%,0,(AQ15*$AR$1+$AR$2)) -> 11000000 | AS15: =AM15-R15-S15-T15 -> 19370000 | AT15: =ROUND(IF((AS15-AR15-AO15)<0,0,(AS15-AR15-AO15)),0) -> 7834500 | AU15: =ROUND(IF($F15=10%,ROUND(AS15*10%,0),0),0) -> 0 | AV15: =ROUND(IF(AU15>0,0,IF(AT15<5000000,AT15*5%,IF(AT15<10000000,250000+(AT15-5000000)*10%,IF(AT15<18000000,750000+(AT15-10000000)*15%,IF(AT15<32000000,1950000+(AT15-18000000)*20%,IF(AT15<52000000,4750000+(AT15-32000000)*25%,IF(AT15<80000000,9750000+(AT15-52000000)*30%,IF(AT15<400000000,18150000+(AT15-80000000)*35%,0)))))))),0) -> 533450 | AW15: =AM15-AO15-AV15-AU15 -> 19931050 | AZ15: =ROUND(AW15-AX15+AY15,0) -> 19931050 | BA15: =AM15+AP15 -> 22096500 | BJ15: =BA15-#REF! -> #REF! | BK15: =AZ15-#REF! -> #REF! | BL15: =C15=#REF! -> #REF!
A16: 8 | B16: BSM00016 | C16: Lê Hải Linh | D16: linhlh.zenme@gmail.com | E16: NV Marketing | G16: ON | M16: =23000000+H43 -> 24000000 | N16: =M16 -> 24000000 | O16: 5100000 | P16: =N16-(O16+Q16+R16+S16+T16) -> 17020000 | Q16: 250000 | R16: 400000 | S16: 500000 | T16: 730000 | U16: =SUM(W16:Y16) -> 20 | V16: 20 | Y16: 20 | AA16: =SUM(AB16:AD16) -> 24000000 | AB16: =ROUND($H16/V16*W16,0) -> 0 | AC16: =ROUND(J16/V16*X16,0) -> 0 | AD16: =ROUND($N16/V16*Y16,0) -> 24000000 | AF16: =SUM(AG16:AL16) -> 0 | AM16: =AA16+AF16 -> 24000000 | AN16: 5100000 | AO16: =$AN16*$AO$1 -> 535500 | AP16: =$AN16*$AP$1 -> 1096500 | AR16: =IF($F16=10%,0,(AQ16*$AR$1+$AR$2)) -> 11000000 | AS16: =AM16-R16-S16-T16 -> 22370000 | AT16: =ROUND(IF((AS16-AR16-AO16)<0,0,(AS16-AR16-AO16)),0) -> 10834500 | AU16: =ROUND(IF($F16=10%,ROUND(AS16*10%,0),0),0) -> 0 | AV16: =ROUND(IF(AU16>0,0,IF(AT16<5000000,AT16*5%,IF(AT16<10000000,250000+(AT16-5000000)*10%,IF(AT16<18000000,750000+(AT16-10000000)*15%,IF(AT16<32000000,1950000+(AT16-18000000)*20%,IF(AT16<52000000,4750000+(AT16-32000000)*25%,IF(AT16<80000000,9750000+(AT16-52000000)*30%,IF(AT16<400000000,18150000+(AT16-80000000)*35%,0)))))))),0) -> 875175 | AW16: =AM16-AO16-AV16-AU16 -> 22589325 | AZ16: =ROUND(AW16-AX16+AY16,0) -> 22589325 | BA16: =AM16+AP16 -> 25096500 | BJ16: =BA16-#REF! -> #REF! | BK16: =AZ16-#REF! -> #REF! | BL16: =C16=#REF! -> #REF!
A17: 9 | B17: BSM00013 | C17: Cao Nguyễn Nguyệt Linh | D17: cnguyetlinh@gmail.com | E17: NV Marketing | G17: ON | M17: 8535500 | N17: =M17 -> 8535500 | O17: 5100000 | P17: =N17-(O17+Q17+R17+S17+T17) -> 1555500 | Q17: 250000 | R17: 400000 | S17: 500000 | T17: 730000 | U17: =SUM(W17:Y17) -> 20 | V17: 20 | Y17: 20 | AA17: =SUM(AB17:AD17) -> 8535500 | AB17: =ROUND($H17/V17*W17,0) -> 0 | AC17: =ROUND(J17/V17*X17,0) -> 0 | AD17: =ROUND($N17/V17*Y17,0) -> 8535500 | AF17: =SUM(AG17:AL17) -> 0 | AM17: =AA17+AF17 -> 8535500 | AN17: 5100000 | AO17: =$AN17*$AO$1 -> 535500 | AP17: =$AN17*$AP$1 -> 1096500 | AR17: =IF($F17=10%,0,(AQ17*$AR$1+$AR$2)) -> 11000000 | AS17: =AM17-R17-S17-T17 -> 6905500 | AT17: =ROUND(IF((AS17-AR17-AO17)<0,0,(AS17-AR17-AO17)),0) -> 0 | AU17: =ROUND(IF($F17=10%,ROUND(AS17*10%,0),0),0) -> 0 | AV17: =ROUND(IF(AU17>0,0,IF(AT17<5000000,AT17*5%,IF(AT17<10000000,250000+(AT17-5000000)*10%,IF(AT17<18000000,750000+(AT17-10000000)*15%,IF(AT17<32000000,1950000+(AT17-18000000)*20%,IF(AT17<52000000,4750000+(AT17-32000000)*25%,IF(AT17<80000000,9750000+(AT17-52000000)*30%,IF(AT17<400000000,18150000+(AT17-80000000)*35%,0)))))))),0) -> 0 | AW17: =AM17-AO17-AV17-AU17 -> 8000000 | AZ17: =ROUND(AW17-AX17+AY17,0) -> 8000000 | BA17: =AM17+AP17 -> 9632000 | BJ17: =BA17-#REF! -> #REF! | BK17: =AZ17-#REF! -> #REF! | BL17: =C17=#REF! -> #REF!
A18: 10 | B18: BSM00020 | C18: Nguyễn Minh Hiếu | D18: hieunp131@gmail.com | E18: Lập trình viên | G18: ON | M18: =61423333+H44+150000 -> 63573333 | N18: =M18 -> 63573333 | O18: 20000000 | P18: =N18-(O18+Q18+R18+S18+T18) -> 41443333 | Q18: 500000 | R18: 400000 | S18: 500000 | T18: 730000 | U18: =SUM(W18:Y18) -> 20 | V18: 20 | Y18: 20 | AA18: =SUM(AB18:AD18) -> 63573333 | AB18: =ROUND($H18/V18*W18,0) -> 0 | AC18: =ROUND(J18/V18*X18,0) -> 0 | AD18: =ROUND($N18/V18*Y18,0) -> 63573333 | AF18: =SUM(AG18:AL18) -> 0 | AM18: =AA18+AF18 -> 63573333 | AN18: 20000000 | AO18: =$AN18*$AO$1 -> 2100000 | AP18: =$AN18*$AP$1 -> 4300000 | AQ18: 2 | AR18: =IF($F18=10%,0,(AQ18*$AR$1+$AR$2)) -> 19800000 | AS18: =AM18-R18-S18-T18 -> 61943333 | AT18: =ROUND(IF((AS18-AR18-AO18)<0,0,(AS18-AR18-AO18)),0) -> 40043333 | AU18: =ROUND(IF($F18=10%,ROUND(AS18*10%,0),0),0) -> 0 | AV18: =ROUND(IF(AU18>0,0,IF(AT18<5000000,AT18*5%,IF(AT18<10000000,250000+(AT18-5000000)*10%,IF(AT18<18000000,750000+(AT18-10000000)*15%,IF(AT18<32000000,1950000+(AT18-18000000)*20%,IF(AT18<52000000,4750000+(AT18-32000000)*25%,IF(AT18<80000000,9750000+(AT18-52000000)*30%,IF(AT18<400000000,18150000+(AT18-80000000)*35%,0)))))))),0) -> 6760833 | AW18: =AM18-AO18-AV18-AU18 -> 54712500 | AZ18: =ROUND(AW18-AX18+AY18,0) -> 54712500 | BA18: =AM18+AP18 -> 67873333 | BI18: Thang 7 cho ra ngoài ko trên prayroll BSM | BJ18: =BA18-#REF! -> #REF! | BK18: =AZ18-#REF! -> #REF! | BL18: =C18=#REF! -> #REF!
A19: 11 | C19: Thái Thanh Nhật Quang | D19: Henry@bsmlabs.io | E19: giám đốc | G19: ON | M19: 98630000 | N19: =M19 -> 98630000 | O19: 20000000 | P19: =N19-(O19+Q19+R19+S19+T19) -> 76250000 | Q19: 250000 | R19: 400000 | S19: 1000000 | T19: 730000 | U19: =SUM(W19:Y19) -> 20 | V19: 20 | Y19: 20 | AA19: =SUM(AB19:AD19) -> 98630000 | AB19: =ROUND($H19/V19*W19,0) -> 0 | AC19: =ROUND(J19/V19*X19,0) -> 0 | AD19: =ROUND($N19/V19*Y19,0) -> 98630000 | AF19: =SUM(AG19:AL19) -> 0 | AM19: =AA19+AF19 -> 98630000 | AN19: 20000000 | AO19: =$AN19*$AO$1 -> 2100000 | AP19: =$AN19*$AP$1 -> 4300000 | AQ19: 2 | AR19: =IF($F19=10%,0,(AQ19*$AR$1+$AR$2)) -> 19800000 | AS19: =AM19-R19-S19-T19 -> 96500000 | AT19: =ROUND(IF((AS19-AR19-AO19)<0,0,(AS19-AR19-AO19)),0) -> 74600000 | AU19: =ROUND(IF($F19=10%,ROUND(AS19*10%,0),0),0) -> 0 | AV19: =ROUND(IF(AU19>0,0,IF(AT19<5000000,AT19*5%,IF(AT19<10000000,250000+(AT19-5000000)*10%,IF(AT19<18000000,750000+(AT19-10000000)*15%,IF(AT19<32000000,1950000+(AT19-18000000)*20%,IF(AT19<52000000,4750000+(AT19-32000000)*25%,IF(AT19<80000000,9750000+(AT19-52000000)*30%,IF(AT19<400000000,18150000+(AT19-80000000)*35%,0)))))))),0) -> 16530000 | AW19: =AM19-AO19-AV19-AU19 -> 80000000 | AZ19: =ROUND(AW19-AX19+AY19,0) -> 80000000 | BA19: =AM19+AP19 -> 102930000
A20: 12 | C20: Trần Minh Tuyết | D20: tuyet.tranminh1973@gmail.com | E20: Kế toán | G20: ON | M20: 14000000 | N20: =M20 -> 14000000 | O20: 9000000 | P20: =N20-(O20+Q20+R20+S20+T20) -> 3120000 | Q20: 250000 | R20: 400000 | S20: 500000 | T20: 730000 | U20: =SUM(W20:Y20) -> 13 | V20: 20 | Y20: 13 | AA20: =SUM(AB20:AD20) -> 9100000 | AB20: =ROUND($H20/V20*W20,0) -> 0 | AC20: =ROUND(J20/V20*X20,0) -> 0 | AD20: =ROUND($N20/V20*Y20,0) -> 9100000 | AM20: =AA20+AF20 -> 9100000 | AN20: 9000000 | AO20: =$AN20*$AO$1 -> 945000 | AP20: =$AN20*$AP$1 -> 1935000 | AQ20: 1 | AR20: =IF($F20=10%,0,(AQ20*$AR$1+$AR$2)) -> 15400000 | AS20: =AM20-R20-S20-T20 -> 7470000 | AT20: =ROUND(IF((AS20-AR20-AO20)<0,0,(AS20-AR20-AO20)),0) -> 0 | AU20: =ROUND(IF($F20=10%,ROUND(AS20*10%,0),0),0) -> 0 | AV20: =ROUND(IF(AU20>0,0,IF(AT20<5000000,AT20*5%,IF(AT20<10000000,250000+(AT20-5000000)*10%,IF(AT20<18000000,750000+(AT20-10000000)*15%,IF(AT20<32000000,1950000+(AT20-18000000)*20%,IF(AT20<52000000,4750000+(AT20-32000000)*25%,IF(AT20<80000000,9750000+(AT20-52000000)*30%,IF(AT20<400000000,18150000+(AT20-80000000)*35%,0)))))))),0) -> 0 | AW20: =AM20-AO20-AV20-AU20 -> 8155000 | AZ20: =ROUND(AW20-AX20+AY20,0) -> 8155000 | BA20: =AM20+AP20 -> 11035000 | BJ20: =BA20-#REF! -> #REF! | BK20: =AZ20-#REF! -> #REF! | BL20: =C20=#REF! -> #REF!
A21: 13 | B21: BSM00023 | C21: Trần Thành Trung | D21: trungtt.bsmlabs@gmail.com | E21: Developer | F21: 0.1 | G21: NEW | J21: =M21*85% -> 23611111 | M21: =25000000/0.9 -> 27777778 | N21: =M21 -> 27777778 | U21: =SUM(W21:Y21) -> 20 | V21: 20 | X21: 20 | Y21: #REF! | AA21: =SUM(AB21:AD21) -> #VALUE! | AB21: =ROUND($H21/V21*W21,0) -> 0 | AC21: =ROUND(J21/V21*X21,0) -> 23611111 | AD21: =ROUND($N21/V21*Y21,0) -> #VALUE! | AF21: =SUM(AG21:AL21) -> 0 | AM21: =AA21+AF21 -> #VALUE! | AN21: 0 | AO21: =$AN21*$AO$1 -> 0 | AP21: =$AN21*$AP$1 -> 0 | AR21: =IF($F21=10%,0,(AQ21*$AR$1+$AR$2)) -> 0 | AS21: =AM21-R21-S21-T21 -> #VALUE! | AT21: =ROUND(IF((AS21-AR21-AO21)<0,0,(AS21-AR21-AO21)),0) -> #VALUE! | AU21: =ROUND(IF($F21=10%,ROUND(AS21*10%,0),0),0) -> #VALUE! | AV21: =ROUND(IF(AU21>0,0,IF(AT21<5000000,AT21*5%,IF(AT21<10000000,250000+(AT21-5000000)*10%,IF(AT21<18000000,750000+(AT21-10000000)*15%,IF(AT21<32000000,1950000+(AT21-18000000)*20%,IF(AT21<52000000,4750000+(AT21-32000000)*25%,IF(AT21<80000000,9750000+(AT21-52000000)*30%,IF(AT21<400000000,18150000+(AT21-80000000)*35%,0)))))))),0) -> #VALUE! | AW21: =AM21-AO21-AV21-AU21 -> #VALUE! | AZ21: =ROUND(AW21-AX21+AY21,0) -> #VALUE! | BA21: =AM21+AP21 -> #VALUE! | BB21: Thử việc | BJ21: =BA21-#REF! -> #VALUE! | BK21: =AZ21-#REF! -> #VALUE! | BL21: =C21=#REF! -> #REF!
A22: 14 | B22: BSM00024 | C22: Đỗ Khánh Huyền | D22: huyendk.bsmlabs@gmail.com | E22: Trợ lý Giám đốc | F22: 0.1 | G22: NEW | J22: =M22*100% -> 27777778 | M22: =25000000/0.9 -> 27777778 | N22: =M22 -> 27777778 | U22: =SUM(W22:Y22) -> 18 | V22: 20 | X22: 18 | Y22: #REF! | AA22: =SUM(AB22:AD22) -> #VALUE! | AB22: =ROUND($H22/V22*W22,0) -> 0 | AC22: =ROUND(J22/V22*X22,0) -> 25000000 | AD22: =ROUND($N22/V22*Y22,0) -> #VALUE! | AF22: =SUM(AG22:AL22) -> 0 | AM22: =AA22+AF22 -> #VALUE! | AO22: =$AN22*$AO$1 -> 0 | AP22: =$AN22*$AP$1 -> 0 | AR22: =IF($F22=10%,0,(AQ22*$AR$1+$AR$2)) -> 0 | AS22: =AM22-R22-S22-T22 -> #VALUE! | AT22: =ROUND(IF((AS22-AR22-AO22)<0,0,(AS22-AR22-AO22)),0) -> #VALUE! | AU22: =ROUND(IF($F22=10%,ROUND(AS22*10%,0),0),0) -> #VALUE! | AV22: =ROUND(IF(AU22>0,0,IF(AT22<5000000,AT22*5%,IF(AT22<10000000,250000+(AT22-5000000)*10%,IF(AT22<18000000,750000+(AT22-10000000)*15%,IF(AT22<32000000,1950000+(AT22-18000000)*20%,IF(AT22<52000000,4750000+(AT22-32000000)*25%,IF(AT22<80000000,9750000+(AT22-52000000)*30%,IF(AT22<400000000,18150000+(AT22-80000000)*35%,0)))))))),0) -> #VALUE! | AW22: =AM22-AO22-AV22-AU22 -> #VALUE! | AZ22: =ROUND(AW22-AX22+AY22,0) -> #VALUE! | BA22: =AM22+AP22 -> #VALUE! | BB22: Thử việc | BJ22: =BA22-#REF! -> #VALUE! | BK22: =AZ22-#REF! -> #VALUE! | BL22: =C22=#REF! -> #REF!
A23: 15 | C23: Nguyễn Tử Trường Lâm | D23: Lamntt.bsmlabs@gmail.com | E23: Video Editor | F23: 0.1 | G23: NEW | J23: =M23*85% -> 11333333 | M23: =12000000/0.9 -> 13333333 | N23: =M23 -> 13333333 | U23: =SUM(W23:Y23) -> 20 | V23: 20 | X23: 20 | Y23: 0 | AA23: =SUM(AB23:AD23) -> 11333333 | AB23: =ROUND($H23/V23*W23,0) -> 0 | AC23: =ROUND(J23/V23*X23,0) -> 11333333 | AD23: =ROUND($N23/V23*Y23,0) -> 0 | AM23: =AA23+AF23 -> 11333333 | AO23: =$AN23*$AO$1 -> 0 | AP23: =$AN23*$AP$1 -> 0 | AR23: =IF($F23=10%,0,(AQ23*$AR$1+$AR$2)) -> 0 | AS23: =AM23-R23-S23-T23 -> 11333333 | AT23: =ROUND(IF((AS23-AR23-AO23)<0,0,(AS23-AR23-AO23)),0) -> 11333333 | AU23: =ROUND(IF($F23=10%,ROUND(AS23*10%,0),0),0) -> 1133333 | AV23: =ROUND(IF(AU23>0,0,IF(AT23<5000000,AT23*5%,IF(AT23<10000000,250000+(AT23-5000000)*10%,IF(AT23<18000000,750000+(AT23-10000000)*15%,IF(AT23<32000000,1950000+(AT23-18000000)*20%,IF(AT23<52000000,4750000+(AT23-32000000)*25%,IF(AT23<80000000,9750000+(AT23-52000000)*30%,IF(AT23<400000000,18150000+(AT23-80000000)*35%,0)))))))),0) -> 0 | AW23: =AM23-AO23-AV23-AU23 -> 10200000 | AZ23: =ROUND(AW23-AX23+AY23,0) -> 10200000 | BA23: =AM23+AP23 -> 11333333 | BB23: Thử việc | BJ23: =BA23-#REF! -> #REF! | BK23: =AZ23-#REF! -> #REF! | BL23: =C23=#REF! -> #REF!
A24: 16 | C24: Lê Anh Việt | D24: vietle.bsmlabs@gmail.com | E24: BD | F24: 0.1 | G24: NEW | J24: =M24*100% -> 10000000 | M24: 10000000 | N24: =M24 -> 10000000 | U24: =SUM(W24:Y24) -> 20 | V24: 20 | X24: 20 | Y24: 0 | AA24: =SUM(AB24:AD24) -> 10000000 | AB24: =ROUND($H24/V24*W24,0) -> 0 | AC24: =ROUND(J24/V24*X24,0) -> 10000000 | AD24: =ROUND($N24/V24*Y24,0) -> 0 | AM24: =AA24+AF24 -> 10000000 | AO24: =$AN24*$AO$1 -> 0 | AP24: =$AN24*$AP$1 -> 0 | AR24: =IF($F24=10%,0,(AQ24*$AR$1+$AR$2)) -> 0 | AS24: =AM24-R24-S24-T24 -> 10000000 | AT24: =ROUND(IF((AS24-AR24-AO24)<0,0,(AS24-AR24-AO24)),0) -> 10000000 | AU24: =ROUND(IF($F24=10%,ROUND(AS24*10%,0),0),0) -> 1000000 | AV24: =ROUND(IF(AU24>0,0,IF(AT24<5000000,AT24*5%,IF(AT24<10000000,250000+(AT24-5000000)*10%,IF(AT24<18000000,750000+(AT24-10000000)*15%,IF(AT24<32000000,1950000+(AT24-18000000)*20%,IF(AT24<52000000,4750000+(AT24-32000000)*25%,IF(AT24<80000000,9750000+(AT24-52000000)*30%,IF(AT24<400000000,18150000+(AT24-80000000)*35%,0)))))))),0) -> 0 | AW24: =AM24-AO24-AV24-AU24 -> 9000000 | AZ24: =ROUND(AW24-AX24+AY24,0) -> 9000000 | BA24: =AM24+AP24 -> 10000000 | BB24: Thử việc | BJ24: =BA24-#REF! -> #REF! | BK24: =AZ24-#REF! -> #REF! | BL24: =C24=#REF! -> #REF!
A25: 17 | C25: Trần Thị Bảo Tâm | D25: tamtran.bsmlabs@gmail.com | E25: HR | F25: 0.1 | G25: NEW | J25: =M25*100% -> 20000000 | M25: =18000000/0.9 -> 20000000 | N25: =M25 -> 20000000 | U25: =SUM(W25:Y25) -> 9 | V25: 20 | X25: 9 | Y25: 0 | AA25: =SUM(AB25:AD25) -> 9000000 | AB25: =ROUND($H25/V25*W25,0) -> 0 | AC25: =ROUND(J25/V25*X25,0) -> 9000000 | AD25: =ROUND($N25/V25*Y25,0) -> 0 | AM25: =AA25+AF25 -> 9000000 | AO25: =$AN25*$AO$1 -> 0 | AP25: =$AN25*$AP$1 -> 0 | AR25: =IF($F25=10%,0,(AQ25*$AR$1+$AR$2)) -> 0 | AS25: =AM25-R25-S25-T25 -> 9000000 | AT25: =ROUND(IF((AS25-AR25-AO25)<0,0,(AS25-AR25-AO25)),0) -> 9000000 | AU25: =ROUND(IF($F25=10%,ROUND(AS25*10%,0),0),0) -> 900000 | AV25: =ROUND(IF(AU25>0,0,IF(AT25<5000000,AT25*5%,IF(AT25<10000000,250000+(AT25-5000000)*10%,IF(AT25<18000000,750000+(AT25-10000000)*15%,IF(AT25<32000000,1950000+(AT25-18000000)*20%,IF(AT25<52000000,4750000+(AT25-32000000)*25%,IF(AT25<80000000,9750000+(AT25-52000000)*30%,IF(AT25<400000000,18150000+(AT25-80000000)*35%,0)))))))),0) -> 0 | AW25: =AM25-AO25-AV25-AU25 -> 8100000 | AZ25: =ROUND(AW25-AX25+AY25,0) -> 8100000 | BA25: =AM25+AP25 -> 9000000 | BB25: Thử việc | BJ25: =BA25-#REF! -> #REF! | BK25: =AZ25-#REF! -> #REF! | BL25: =C25=#REF! -> #REF!
A26: 18 | B26: BSM00017 | C26: Nguyễn Thị Thu Thảo | D26: thuthaonguyenzz620@gmail.com | E26: Thực tập sinh | F26: 0.1 | G26: ON | H26: 11000000 | M26: =H26 -> 11000000 | U26: =SUM(W26:Y26) -> 20 | V26: 20 | W26: 20 | AA26: =SUM(AB26:AD26) -> 11000000 | AB26: =ROUND($H26/V26*W26,0) -> 11000000 | AC26: =ROUND(J26/V26*X26,0) -> 0 | AD26: =ROUND($N26/V26*Y26,0) -> 0 | AF26: =SUM(AG26:AL26) -> 0 | AM26: =AA26+AF26 -> 11000000 | AS26: =AM26-R26-S26-T26 -> 11000000 | AT26: =ROUND(IF((AS26-AR26-AO26)<0,0,(AS26-AR26-AO26)),0) -> 11000000 | AU26: =ROUND(IF($F26=10%,ROUND(AS26*10%,0),0),0) -> 1100000 | AW26: =AM26-AO26-AV26-AU26 -> 9900000 | AX26: 0 | AZ26: =ROUND(AW26-AX26+AY26,0) -> 9900000 | BA26: =AM26+AP26 -> 11000000 | BB26: Intern | BJ26: =BA26-#REF! -> #REF! | BK26: =AZ26-#REF! -> #REF! | BL26: =C26=#REF! -> #REF!
A27: 19 | B27: BSM00021 | C27: Nguyễn Xuân Phong | D27: phongnx.bsmlabs@gmail.com | E27: Thực tập sinh | F27: 0.1 | G27: ON | H27: =5000000/0.9 -> 5555555.6 | M27: =H27 -> 5555555.6 | U27: =SUM(W27:Y27) -> 20 | V27: 20 | W27: 20 | AA27: =SUM(AB27:AE27) -> 5555556 | AB27: =ROUND($H27/V27*W27,0) -> 5555556 | AC27: =ROUND(J27/V27*X27,0) -> 0 | AD27: =ROUND($N27/V27*Y27,0) -> 0 | AF27: =SUM(AG27:AL27) -> 0 | AM27: =AA27+AF27 -> 5555556 | AS27: =AM27-R27-S27-T27 -> 5555556 | AT27: =ROUND(IF((AS27-AR27-AO27)<0,0,(AS27-AR27-AO27)),0) -> 5555556 | AU27: =ROUND(IF($F27=10%,ROUND(AS27*10%,0),0),0) -> 555556 | AW27: =AM27-AO27-AV27-AU27 -> 5000000 | AX27: 0 | AZ27: =ROUND(AW27-AX27+AY27,0) -> 5000000 | BA27: =AM27+AP27 -> 5555556 | BB27: Intern | BI27: Cty trả taxes | BJ27: =BA27-#REF! -> #REF! | BK27: =AZ27-#REF! -> #REF! | BL27: =C27=#REF! -> #REF!
A28: 20 | B28: BSM00022 | C28: Vương Tuấn Cường | D28: cuongvt.bsmlabs@gmail.com | E28: Thực tập sinh | F28: 0.1 | G28: ON | H28: =6000000/0.9 -> 6666666.7 | M28: =H28 -> 6666666.7 | U28: =SUM(W28:Y28) -> 20 | V28: 20 | W28: 20 | AA28: =SUM(AB28:AE28) -> 6666667 | AB28: =ROUND($H28/V28*W28,0) -> 6666667 | AC28: =ROUND(J28/V28*X28,0) -> 0 | AD28: =ROUND($N28/V28*Y28,0) -> 0 | AF28: =SUM(AG28:AL28) -> 0 | AM28: =AA28+AF28 -> 6666667 | AS28: =AM28-R28-S28-T28 -> 6666667 | AT28: =ROUND(IF((AS28-AR28-AO28)<0,0,(AS28-AR28-AO28)),0) -> 6666667 | AU28: =ROUND(IF($F28=10%,ROUND(AS28*10%,0),0),0) -> 666667 | AW28: =AM28-AO28-AV28-AU28 -> 6000000 | AX28: 0 | AZ28: =ROUND(AW28-AX28+AY28,0) -> 6000000 | BA28: =AM28+AP28 -> 6666667 | BB28: Intern | BI28: Cty trả taxes | BJ28: =BA28-#REF! -> #REF! | BK28: =AZ28-#REF! -> #REF! | BL28: =C28=#REF! -> #REF!
A29: 21 | B29: BSM00025 | C29: Nguyễn Nam Anh | D29: anhnn.bsmlabs@gmail.com | E29: Thực tập sinh | F29: 0.1 | G29: NEW | H29: =4000000/0.9 -> 4444444.4 | M29: =H29 -> 4444444.4 | U29: =SUM(W29:Y29) -> 19 | V29: 20 | W29: 19 | AA29: =SUM(AB29:AE29) -> 4222222 | AB29: =ROUND($H29/V29*W29,0) -> 4222222 | AC29: =ROUND(J29/V29*X29,0) -> 0 | AD29: =ROUND($N29/V29*Y29,0) -> 0 | AF29: =SUM(AG29:AL29) -> 0 | AM29: =AA29+AF29 -> 4222222 | AS29: =AM29-R29-S29-T29 -> 4222222 | AT29: =ROUND(IF((AS29-AR29-AO29)<0,0,(AS29-AR29-AO29)),0) -> 4222222 | AU29: =ROUND(IF($F29=10%,ROUND(AS29*10%,0),0),0) -> 422222 | AW29: =AM29-AO29-AV29-AU29 -> 3800000 | AX29: 0 | AZ29: =ROUND(AW29-AX29+AY29,0) -> 3800000 | BA29: =AM29+AP29 -> 4222222 | BB29: Intern | BI29: Cty trả taxes | BJ29: =BA29-#REF! -> #REF! | BK29: =AZ29-#REF! -> #REF! | BL29: =C29=#REF! -> #REF!
A30: 22 | B30: BSM00026 | C30: Ngô Phương Anh | E30: Thực tập sinh | F30: 0.1 | G30: NEW | H30: =5000000/0.9 -> 5555555.6 | M30: =H30 -> 5555555.6 | U30: =SUM(W30:Y30) -> 19 | V30: 20 | W30: 19 | AA30: =SUM(AB30:AE30) -> 5277778 | AB30: =ROUND($H30/V30*W30,0) -> 5277778 | AC30: =ROUND(J30/V30*X30,0) -> 0 | AD30: =ROUND($N30/V30*Y30,0) -> 0 | AF30: =SUM(AG30:AL30) -> 0 | AM30: =AA30+AF30 -> 5277778 | AS30: =AM30-R30-S30-T30 -> 5277778 | AT30: =ROUND(IF((AS30-AR30-AO30)<0,0,(AS30-AR30-AO30)),0) -> 5277778 | AU30: =ROUND(IF($F30=10%,ROUND(AS30*10%,0),0),0) -> 527778 | AW30: =AM30-AO30-AV30-AU30 -> 4750000 | AX30: 0 | AZ30: =ROUND(AW30-AX30+AY30,0) -> 4750000 | BA30: =AM30+AP30 -> 5277778 | BB30: Intern | BI30: Cty trả taxes | BJ30: =BA30-#REF! -> #REF! | BK30: =AZ30-#REF! -> #REF! | BL30: =C30=#REF! -> #REF!
A31: 23 | C31: Nguyễn Văn Tuấn | D31: tuannv140301@gmail.com | E31: AI Intern | F31: 0.1 | G31: ON | H31: 5000000 | M31: =H31 -> 5000000 | U31: =SUM(W31:Y31) -> 11.5 | V31: 20 | W31: 11.5 | AA31: =SUM(AB31:AE31) -> 2875000 | AB31: =ROUND($H31/V31*W31,0) -> 2875000 | AC31: =ROUND(J31/V31*X31,0) -> 0 | AD31: =ROUND($N31/V31*Y31,0) -> 0 | AF31: =SUM(AG31:AL31) -> 0 | AM31: =AA31+AF31 -> 2875000 | AS31: =AM31-R31-S31-T31 -> 2875000 | AT31: =ROUND(IF((AS31-AR31-AO31)<0,0,(AS31-AR31-AO31)),0) -> 2875000 | AU31: =ROUND(IF($F31=10%,ROUND(AS31*10%,0),0),0) -> 287500 | AW31: =AM31-AO31-AV31-AU31 -> 2587500 | AX31: 0 | AZ31: =ROUND(AW31-AX31+AY31,0) -> 2587500 | BA31: =AM31+AP31 -> 2875000 | BB31: Intern | BJ31: =BA31-#REF! -> #REF! | BK31: =AZ31-#REF! -> #REF! | BL31: =C31=#REF! -> #REF!
A32: 24 | C32: Đặng Phương Anh | D32: phuonganhd.bsmlabs@gmail.com | E32: AI Intern | G32: NEW | H32: 3000000 | M32: =H32 -> 3000000 | U32: =SUM(W32:Y32) -> 7 | V32: 20 | W32: 7 | AA32: =SUM(AB32:AE32) -> 1050000 | AB32: =ROUND($H32/V32*W32,0) -> 1050000 | AC32: =ROUND(J32/V32*X32,0) -> 0 | AD32: =ROUND($N32/V32*Y32,0) -> 0 | AF32: =SUM(AG32:AL32) -> 0 | AM32: =AA32+AF32 -> 1050000 | AS32: =AM32-R32-S32-T32 -> 1050000 | AT32: =ROUND(IF((AS32-AR32-AO32)<0,0,(AS32-AR32-AO32)),0) -> 1050000 | AU32: =ROUND(IF($F32=10%,ROUND(AS32*10%,0),0),0) -> 0 | AW32: =AM32-AO32-AV32-AU32 -> 1050000 | AX32: 0 | AZ32: =ROUND(AW32-AX32+AY32,0) -> 1050000 | BA32: =AM32+AP32 -> 1050000 | BB32: Intern | BI32: Cty trả taxes | BJ32: =BA32-#REF! -> #REF! | BK32: =AZ32-#REF! -> #REF! | BL32: =C32=#REF! -> #REF!
A33: 25 | C33: Nguyễn Hải Anh | D33: anhnth@sotanext.com | E33: CTV Admin | H33: 2500000 | M33: =H33 -> 2500000 | U33: =SUM(W33:Y33) -> 13 | V33: 20 | W33: 13 | AA33: =SUM(AB33:AE33) -> 1625000 | AB33: =ROUND($H33/V33*W33,0) -> 1625000 | AC33: =ROUND(J33/V33*X33,0) -> 0 | AD33: =ROUND($N33/V33*Y33,0) -> 0 | AF33: =SUM(AG33:AL33) -> 0 | AM33: =AA33+AF33 -> 1625000 | AS33: =AM33-R33-S33-T33 -> 1625000 | AT33: =ROUND(IF((AS33-AR33-AO33)<0,0,(AS33-AR33-AO33)),0) -> 1625000 | AU33: =ROUND(IF($F33=10%,ROUND(AS33*10%,0),0),0) -> 0 | AW33: =AM33-AO33-AV33-AU33 -> 1625000 | AZ33: =ROUND(AW33-AX33+AY33,0) -> 1625000 | BA33: =AM33+AP33 -> 1625000 | BB33: CTV | BJ33: =BA33-#REF! -> #REF! | BK33: =AZ33-#REF! -> #REF! | BL33: =C33=#REF! -> #REF!
B34: Lương tăng ngoài | AW34: =AM34-AO34-AV34-AU34 -> 0
A35: 1 | C35: Nguyễn Hải Anh | E35: HR | H35: 2500000 | U35: 23 | V35: 23 | AA35: =IFERROR(ROUND(H35/V35*U35,0),0) -> 2500000 | AE35: 0 | AM35: =AA35+AF35 -> 2500000
A36: =A35+1 -> 2 | B36: BSM00002 | C36: Bùi Văn Điệp | E36: Lập trình viên | H36: 23500000 | U36: =IFERROR(VLOOKUP(C36,$C$9:$U$27,19,0),0) -> 20 | V36: =IFERROR(VLOOKUP(C36,$C$9:$V$27,20,0),0) -> 20 | AA36: =IFERROR(ROUND(H36/V36*U36,0),0) -> 23500000 | AE36: 0 | AM36: =AA36+AF36 -> 23500000 | AW36: =AM36-AO36-AV36-AU36 -> 23500000 | AZ36: =ROUND(AW36-AX36+AY36,0) -> 23500000 | BA36: =AM36+AP36 -> 23500000 | BB36: Lương tăng ngoài dành cho nv chính thức
A37: =A36+1 -> 3 | B37: BSM00001 | C37: Nguyễn Châu Hy | H37: 1000000 | U37: =IFERROR(VLOOKUP(C37,$C$9:$U$27,19,0),0) -> 10 | V37: =IFERROR(VLOOKUP(C37,$C$9:$V$27,20,0),0) -> 20 | AA37: =IFERROR(ROUND(H37/V37*U37,0),0) -> 500000 | AE37: 0 | AM37: =AA37+AF37 -> 500000 | AW37: =AM37-AO37-AV37-AU37 -> 500000 | AZ37: =ROUND(AW37-AX37+AY37,0) -> 500000 | BA37: =AM37+AP37 -> 500000 | BB37: Lương tăng ngoài dành cho nv chính thức
A38: =A37+1 -> 4 | B38: BSM00003 | C38: Nguyễn Ngọc Anh | H38: 4000000 | U38: =IFERROR(VLOOKUP(C38,$C$9:$U$27,19,0),0) -> 20 | V38: =IFERROR(VLOOKUP(C38,$C$9:$V$27,20,0),0) -> 20 | AA38: =IFERROR(ROUND(H38/V38*U38,0),0) -> 4000000 | AE38: 0 | AM38: =AA38+AF38 -> 4000000 | AW38: =AM38-AO38-AV38-AU38 -> 4000000 | AZ38: =ROUND(AW38-AX38+AY38,0) -> 4000000 | BA38: =AM38+AP38 -> 4000000 | BB38: Lương tăng ngoài dành cho nv chính thức
A39: =A38+1 -> 5 | B39: BSM00005 | C39: Phan Thanh Tùng | H39: 1000000 | U39: =IFERROR(VLOOKUP(C39,$C$9:$U$27,19,0),0) -> 20 | V39: =IFERROR(VLOOKUP(C39,$C$9:$V$27,20,0),0) -> 20 | AA39: =IFERROR(ROUND(H39/V39*U39,0),0) -> 1000000 | AE39: 0 | AM39: =AA39+AF39 -> 1000000 | AW39: =AM39-AO39-AV39-AU39 -> 1000000 | AZ39: =ROUND(AW39-AX39+AY39,0) -> 1000000 | BA39: =AM39+AP39 -> 1000000 | BB39: Lương tăng ngoài dành cho nv chính thức
A40: =A39+1 -> 6 | B40: BSM00006 | C40: Nguyễn Thị Hà | H40: 1000000 | U40: =IFERROR(VLOOKUP(C40,$C$9:$U$27,19,0),0) -> 20 | V40: =IFERROR(VLOOKUP(C40,$C$9:$V$27,20,0),0) -> 20 | AA40: =IFERROR(ROUND(H40/V40*U40,0),0) -> 1000000 | AE40: 0 | AM40: =AA40+AF40 -> 1000000 | AW40: =AM40-AO40-AV40-AU40 -> 1000000 | AZ40: =ROUND(AW40-AX40+AY40,0) -> 1000000 | BA40: =AM40+AP40 -> 1000000 | BB40: Lương tăng ngoài dành cho nv chính thức
...

Sheet Lương 032026_Chốt
A1: Công ty CP BSM LABS | AZ1: 142000
AM2: =AM24-1630000 -> 10370000 | AZ2: 558000 | BL2: Chốt | BP2: 13358652
A3: BẢNG LƯƠNG THÁNG 03/2026 | BL3: Tổng lương thực nhận | BN3: =SUM(AZ9:AZ37) -> -248086000 | BO3: =BN3+BN4 -> 157008213 | BP3: 472375765
A4: THÔNG TIN NHÂN VIÊN | G4: TỔNG LƯƠNG GROSS | U4: NGÀY CÔNG TÍNH LƯƠNG | AA4: LƯƠNG THEO NGÀY CÔNG | AF4: CÁC KHOẢN THU NHẬP/GIẢM TRỪ KHÁC | AM4: TỔNG THU NHẬP (32=17+22+25) | AN4: BHXH | AQ4: THUẾ TNCN | AW4: THỰC LĨNH | BA4: TỔNG CHI PHÍ LƯƠNG, THƯỞNG | BB4: Note | BL4: Tổng chi phí lương, thưởng | BN4: =SUM(BA9:BA37) -> 405094213
A5: STT | B5: Họ và tên | C5: Email | D5: Vị trí | E5: Thuế | F5: Code | G5: CTV/thực tập | I5: Nhân viên thử việc | L5: Tổng lương gross | M5: Nhân viên chính thức | U5: Tổng ngày công | V5: Ngày công chuẩn | W5: Ngày công CTV / thực tập | X5: Ngày công thử việc | Y5: Ngày công chính thức | Z5: Ngày công trước khi điều chỉnh lương | AA5: Tổng lương theo ngày công (16= 17+18+19 | AB5: Lương ngày công CTV / thực tập | AC5: Lương ngày công thử việc | AD5: Lương ngày công chính thức | AE5: Lương ngày công CTV / thực tập trước ĐC | AF5: Các khoản tăng/giảm khác (23=24+25+26+27+28+29+30) | AG5: OT không chịu thuế | AH5: Các khoản bổ sung khác | AI5: Hỗ trợ nhà ở | AJ5: Thưởng (Doanh số, Hiệu quả, Thành tích đặc biệt,…) | AK5: Incentive Power Up / EDU | AL5: Bonus/Lương tháng 13 | AN5: Mức lương đóng BHXH | AO5: BHXH NV đóng (10.5%* lương cơ bản) | AP5: BHXH Công ty đóng (21.5%* lương cơ bản) | AQ5: Tổng số người phụ thuộc | AR5: Giảm trừ bản thân và giảm trừ NPT | AS5: Thu nhập chịu thuế | AT5: Thu nhập tính thuế | AU5: Thuế TNCN | AW5: Tổng thu nhập sau thuế | AX5: Các khoản trừ ngoài lương (-) ( tạm ứng lương, truy thu thuế TNCN…) | AY5: Các khoản cộng ngoài lương (+) ( truy lĩnh thuế TNCN, bù trừ lương tháng ....) | AZ5: LƯƠNG THỰC NHẬN (44=41-42+43 | BK5: Cần chú ý | BQ5: 549869632
G6: Tổng lương CTV / thực tập | H6: Tổng lương CTV / thực tập trước ĐC | I6: Tổng lương thử việc (2=3+4) | J6: Lương thử việc | K6: Hỗ trợ ăn trưa | M6: Tổng lương | N6: Lương cơ bản | O6: Thưởng hiệu suất | P6: Xăng xe | Q6: Hỗ trợ Đồng phục | R6: Hỗ trợ điện thoại | S6: Hỗ trợ ăn trưa | T6: PC ko chịu thuế TNCN | AU6: Thuế 10% | AV6: Thuế lũy tiến | BC6: Công thực tế T01 thiếu | BD6: tăng/giảm khác T01 | BE6: tăng/giảm khác T12 | BF6: PC ko chịu thuế TNCN theo ngày công tte | BG6: Lương tháng 12 | BH6: Công tháng 12 thiếu | BI6: CL lương ( tháng này - tháng trước) | BJ6: Lý do CL lương | BL6: Tài khoản NH | BN6: Số TK | BQ6: =BQ5-BN4 -> 144775419
G7: VND | H7: VND | I7: VND | J7: VND | K7: VND | L7: VND | M7: VND | N7: VND | O7: VND | P7: VND | Q7: VND | R7: VND | S7: VND | T7: VND | U7: Ngày | V7: Ngày | W7: Ngày | X7: Ngày | Y7: Ngày | AA7: VND | AB7: VND | AC7: VND | AD7: VND | AF7: VND | AG7: VND | AH7: VND | AI7: VND | AJ7: VND | AL7: VND | AM7: VND | AN7: VND | AO7: VND | AP7: VND | AQ7: Người | AR7: VNĐ | AS7: VNĐ | AT7: VNĐ | AV7: VNĐ | AW7: VNĐ | AX7: VNĐ | AY7: VNĐ | AZ7: VNĐ | BA7: VNĐ | BC7: Chuẩn 22 ngày | BH7: Chuẩn 23 ngày
G8: 1 | I8: 2 | J8: 3 | K8: 4 | L8: 5 | M8: 5 | N8: 6 | O8: 7 | Q8: 8 | R8: 9 | S8: 10 | U8: 11 | V8: 12 | W8: 13 | X8: 14 | Y8: 15 | AA8: 16 | AB8: 17 | AC8: 18 | AD8: 19 | AF8: 23 | AG8: 24 | AH8: 26 | AI8: 27 | AJ8: 28 | AK8: 29 | AL8: 30 | AM8: 31 | AN8: 32 | AO8: 33 | AP8: 34 | AQ8: 35 | AR8: 36 | AS8: 37 | AT8: 38 | AU8: 39 | AV8: 40 | AW8: 41 | AX8: 42 | AY8: 43 | AZ8: 44 | BA8: 47 | BM8: Số TK Ngân hàng T12 | BN8: Ngân hàng T12 | BO8: Số TK Ngân hàng cũ | BP8: Ngân hàng cũ | BR8: Nhóm lương | BT8: Thực lĩnh gốc | BU8: Incentive
A9: NET | B9: Bùi Văn Điệp | C9: chuaco@congty.cty | D9: CTO | F9: ON | L9: 20000000 | M9: =L9 -> 20000000 | N9: =VLOOKUP(B9,BHXH!$E$7:$F$20,2,0) -> 5310000 | O9: =M9-(N9+P9+Q9+R9+S9) -> 12060000 | P9: 500000 | Q9: 400000 | R9: 1000000 | S9: 730000 | T9: =SUM(Q9:S9) -> 2130000 | U9: =SUM(W9:Y9) -> 22 | V9: 22 | Y9: =VLOOKUP(B9, 'Thưởng hiệu suất'!$B:$D,3,0) -> 22 | AA9: =SUM(AB9:AD9) -> 20000000 | AB9: =ROUND($G9/V9*W9,0) -> 0 | AC9: =ROUND(I9/V9*X9,0) -> 0 | AD9: =ROUND($M9/V9*Y9,0) -> 20000000 | AF9: =SUM(AG9:AL9) -> 0 | AG9: =SUMIF('Tổng hợp OT'!B:B,B9,'Tổng hợp OT'!D:D) -> 0 | AJ9: =-VLOOKUP(B9,'Thưởng hiệu suất'!$B$3:$D$36,2,0) -> 0 | AM9: =AA9+AF9 -> 20000000 | AN9: =VLOOKUP(B9,BHXH!$E$7:$F$17,2,0) -> 5310000 | AO9: =$AN9*10.5% -> 557550 | AP9: =$AN9*21.5% -> 1141650 | AQ9: 3 | AR9: =IF($E9=10%,0,(AQ9*6200000+15500000)) -> 34100000 | AS9: =AM9-(Q9+R9+S9)/V9*U9-AG9 -> 17870000 | AT9: =ROUND(IF((AS9-AR9-AO9)<0,0,(AS9-AR9-AO9)),0) -> 0 | AV9: =IF(AT9<=0,0,IF(AT9<=10000000,AT9*5%,IF(AT9<=30000000,AT9*10%-500000,IF(AT9<=60000000,AT9*20%-3500000,IF(AT9<=100000000,AT9*30%-9500000,AT9*35%-14500000))))) -> 0 | AW9: =ROUND((AM9-AO9-AV9-AU9),-3) -> 19442000 | AX9: 55000000 | AZ9: =ROUND(AW9-AX9+AY9,0) -> -35558000 | BA9: =AM9+AP9 -> 21141650 | BC9: =(U9-V9) -> 0 | BD9: =AF9 -> 0 | BE9: 0 | BF9: =T9 -> 2130000 | BG9: 55000000 | BH9: 0 | BI9: =AW9-BG9 -> -35558000 | BK9: Bùi Văn Điệp | BL9: BUI VAN DIEP | BM9: 0945661904 | BN9: VIET NAM THINH VUONG (VPBANK)-309 | BO9: 11520619487015 | BP9: TCB | BQ9: Bùi Văn Điệp | BR9: NET | BS9: Bùi Văn Điệp | BW9: 57475000 | BX9: =L9-BW9 -> -37475000
A10: NET | B10: Nguyễn Ngọc Anh | C10: ssinz7.zenme@gmail.com | D10: Lập trình viên | F10: ON | L10: =L9-1000000 -> 19000000 | M10: =L10 -> 19000000 | N10: =VLOOKUP(B10,BHXH!$E$7:$F$20,2,0) -> 5310000 | O10: =M10-(N10+P10+Q10+R10+S10) -> 11310000 | P10: 250000 | Q10: 400000 | R10: 1000000 | S10: 730000 | T10: =SUM(Q10:S10) -> 2130000 | U10: =SUM(W10:Y10) -> 22 | V10: 22 | Y10: =VLOOKUP(B10, 'Thưởng hiệu suất'!$B:$D,3,0) -> 22 | AA10: =SUM(AB10:AD10) -> 19000000 | AB10: =ROUND($G10/V10*W10,0) -> 0 | AC10: =ROUND(I10/V10*X10,0) -> 0 | AD10: =ROUND($M10/V10*Y10,0) -> 19000000 | AF10: =SUM(AG10:AL10) -> 0 | AG10: =SUMIF('Tổng hợp OT'!B:B,B10,'Tổng hợp OT'!D:D) -> 0 | AJ10: =-VLOOKUP(B10,'Thưởng hiệu suất'!$B$3:$D$36,2,0) -> 0 | AM10: =AA10+AF10 -> 19000000 | AN10: =VLOOKUP(B10,BHXH!$E$7:$F$17,2,0) -> 5310000 | AO10: =$AN10*10.5% -> 557550 | AP10: =$AN10*21.5% -> 1141650 | AQ10: 0 | AR10: =IF($E10=10%,0,(AQ10*6200000+15500000)) -> 15500000 | AS10: =AM10-(Q10+R10+S10)/V10*U10-AG10 -> 16870000 | AT10: =ROUND(IF((AS10-AR10-AO10)<0,0,(AS10-AR10-AO10)),0) -> 812450 | AV10: =IF(AT10<=0,0,IF(AT10<=10000000,AT10*5%,IF(AT10<=30000000,AT10*10%-500000,IF(AT10<=60000000,AT10*20%-3500000,IF(AT10<=100000000,AT10*30%-9500000,AT10*35%-14500000))))) -> 40622.5 | AW10: =ROUND((AM10-AO10-AV10-AU10),-3) -> 18402000 | AX10: 38000000 | AZ10: =ROUND(AW10-AX10+AY10,0) -> -19598000 | BA10: =AM10+AP10 -> 20141650 | BC10: =(U10-V10) -> 0 | BD10: =AF10 -> 0 | BE10: 0 | BF10: =T10 -> 2130000 | BG10: 38000000 | BH10: 0 | BI10: =AW10-BG10 -> -19598000 | BK10: Nguyễn Ngọc Anh | BL10: NGUYEN NGOC ANH | BM10: 19034415575011 | BN10: TCB | BO10: 19034415575011 | BP10: TCB | BQ10: Nguyễn Ngọc Anh | BR10: NET | BS10: Nguyễn Ngọc Anh | BW10: 40265328 | BX10: =L10-BW10 -> -21265328
A11: NET | B11: Lê Hải Linh | C11: linhlh.zenme@gmail.com | D11: NV Marketing | F11: ON | L11: =L10-1000000 -> 18000000 | M11: =L11 -> 18000000 | N11: =VLOOKUP(B11,BHXH!$E$7:$F$20,2,0) -> 5310000 | O11: =M11-(N11+P11+Q11+R11+S11) -> 10810000 | P11: 250000 | Q11: 400000 | R11: 500000 | S11: 730000 | T11: =SUM(Q11:S11) -> 1630000 | U11: =SUM(W11:Y11) -> 10 | V11: 22 | Y11: =VLOOKUP(B11, 'Thưởng hiệu suất'!$B:$D,3,0) -> 10 | AA11: =SUM(AB11:AD11) -> 8181818 | AB11: =ROUND($G11/V11*W11,0) -> 0 | AC11: =ROUND(I11/V11*X11,0) -> 0 | AD11: =ROUND($M11/V11*Y11,0) -> 8181818 | AF11: =SUM(AG11:AL11) -> -225000 | AG11: =SUMIF('Tổng hợp OT'!B:B,B11,'Tổng hợp OT'!D:D) -> 0 | AJ11: =-VLOOKUP(B11,'Thưởng hiệu suất'!$B$3:$D$36,2,0) -> -225000 | AM11: =AA11+AF11 -> 7956818 | AN11: =VLOOKUP(B11,BHXH!$E$7:$F$17,2,0) -> 5310000 | AO11: =$AN11*10.5% -> 557550 | AP11: =$AN11*21.5% -> 1141650 | AQ11: 0 | AR11: =IF($E11=10%,0,(AQ11*6200000+15500000)) -> 15500000 | AS11: =AM11-(Q11+R11+S11)/V11*U11-AG11 -> 7215908.9 | AT11: =ROUND(IF((AS11-AR11-AO11)<0,0,(AS11-AR11-AO11)),0) -> 0 | AV11: =IF(AT11<=0,0,IF(AT11<=10000000,AT11*5%,IF(AT11<=30000000,AT11*10%-500000,IF(AT11<=60000000,AT11*20%-3500000,IF(AT11<=100000000,AT11*30%-9500000,AT11*35%-14500000))))) -> 0 | AW11: =ROUND((AM11-AO11-AV11-AU11),-3) -> 7399000 | AZ11: =ROUND(AW11-AX11+AY11,0) -> 7399000 | BA11: =AM11+AP11 -> 9098468 | BC11: =(U11-V11) -> -12 | BD11: =AF11 -> -225000 | BE11: -450000 | BF11: =T11 -> 1630000 | BG11: 23710000 | BH11: 0 | BI11: =AW11-BG11 -> -16311000 | BJ11: T3 chỉ có 8 ngày công | BK11: Lê Hải Linh | BL11: LE HAI LINH | BM11: 222638429 | BN11: VIET NAM THINH VUONG (VPBANK)-309 | BO11: 222638429 | BP11: VIET NAM THINH VUONG (VPBANK)-309 | BQ11: Lê Hải Linh | BR11: GROSS | BS11: Lê Hải Linh | BW11: 24913866 | BX11: =L11-BW11 -> -6913865.8
A12: NET | B12: Thái Thanh Nhật Quang | C12: Henry@bsmlabs.io | D12: CEO | F12: ON | L12: =L11-1000000 -> 17000000 | M12: =L12 -> 17000000 | N12: =VLOOKUP(B12,BHXH!$E$7:$F$20,2,0) -> 5310000 | O12: =M12-(N12+P12+Q12+R12+S12) -> 9310000 | P12: 250000 | Q12: 400000 | R12: 1000000 | S12: 730000 | T12: =SUM(Q12:S12) -> 2130000 | U12: =SUM(W12:Y12) -> 22 | V12: 22 | Y12: =VLOOKUP(B12, 'Thưởng hiệu suất'!$B:$D,3,0) -> 22 | AA12: =SUM(AB12:AD12) -> 17000000 | AB12: =ROUND($G12/V12*W12,0) -> 0 | AC12: =ROUND(I12/V12*X12,0) -> 0 | AD12: =ROUND($M12/V12*Y12,0) -> 17000000 | AF12: =SUM(AG12:AL12) -> 0 | AG12: =SUMIF('Tổng hợp OT'!B:B,B12,'Tổng hợp OT'!D:D) -> 0 | AJ12: =-VLOOKUP(B12,'Thưởng hiệu suất'!$B$3:$D$36,2,0) -> 0 | AM12: =AA12+AF12 -> 17000000 | AN12: =VLOOKUP(B12,BHXH!$E$7:$F$17,2,0) -> 5310000 | AO12: =$AN12*10.5% -> 557550 | AP12: =$AN12*21.5% -> 1141650 | AQ12: 2 | AR12: =IF($E12=10%,0,(AQ12*6200000+15500000)) -> 27900000 | AS12: =AM12-(Q12+R12+S12)/V12*U12-AG12 -> 14870000 | AT12: =ROUND(IF((AS12-AR12-AO12)<0,0,(AS12-AR12-AO12)),0) -> 0 | AV12: =IF(AT12<=0,0,IF(AT12<=10000000,AT12*5%,IF(AT12<=30000000,AT12*10%-500000,IF(AT12<=60000000,AT12*20%-3500000,IF(AT12<=100000000,AT12*30%-9500000,AT12*35%-14500000))))) -> 0 | AW12: =ROUND((AM12-AO12-AV12-AU12),-3) -> 16442000 | AX12: 80000000 | AZ12: =ROUND(AW12-AX12+AY12,0) -> -63558000 | BA12: =AM12+AP12 -> 18141650 | BC12: =(U12-V12) -> 0 | BD12: =AF12 -> 0 | BE12: 0 | BF12: =T12 -> 2130000 | BG12: 80000000 | BH12: 0 | BI12: =AW12-BG12 -> -63558000 | BK12: Thái Thanh Nhật Quang | BL12: THAI THANH NHAT QUANG | BM12: 19037989444011 | BN12: TCB | BO12: 19037989444011 | BP12: TCB | BQ12: Thái Thanh Nhật Quang | BR12: NET | BS12: Thái Thanh Nhật Quang | BW12: 90217500 | BX12: =L12-BW12 -> -73217500
A13: 5 | B13: Trần Minh Tuyết | C13: tuyet.tranminh1973@gmail.com | D13: KTT | F13: ON | L13: =L12-1000000 -> 16000000 | M13: =L13 -> 16000000 | N13: =VLOOKUP(B13,BHXH!$E$7:$F$20,2,0) -> 5310000 | O13: =M13-(N13+P13+Q13+R13+S13) -> 8810000 | P13: 250000 | Q13: 400000 | R13: 500000 | S13: 730000 | T13: =SUM(Q13:S13) -> 1630000 | U13: =SUM(W13:Y13) -> 22 | V13: 22 | Y13: =VLOOKUP(B13, 'Thưởng hiệu suất'!$B:$D,3,0) -> 22 | AA13: =SUM(AB13:AD13) -> 16000000 | AB13: =ROUND($G13/V13*W13,0) -> 0 | AC13: =ROUND(I13/V13*X13,0) -> 0 | AD13: =ROUND($M13/V13*Y13,0) -> 16000000 | AF13: =SUM(AG13:AL13) -> 0 | AG13: =SUMIF('Tổng hợp OT'!B:B,B13,'Tổng hợp OT'!D:D) -> 0 | AJ13: =-VLOOKUP(B13,'Thưởng hiệu suất'!$B$3:$D$36,2,0) -> 0 | AM13: =AA13+AF13 -> 16000000 | AN13: =VLOOKUP(B13,BHXH!$E$7:$F$17,2,0) -> 5310000 | AO13: =$AN13*10.5% -> 557550 | AP13: =$AN13*21.5% -> 1141650 | AQ13: 0 | AR13: =IF($E13=10%,0,(AQ13*6200000+15500000)) -> 15500000 | AS13: =AM13-(Q13+R13+S13)/V13*U13-AG13 -> 14370000 | AT13: =ROUND(IF((AS13-AR13-AO13)<0,0,(AS13-AR13-AO13)),0) -> 0 | AV13: =IF(AT13<=0,0,IF(AT13<=10000000,AT13*5%,IF(AT13<=30000000,AT13*10%-500000,IF(AT13<=60000000,AT13*20%-3500000,IF(AT13<=100000000,AT13*30%-9500000,AT13*35%-14500000))))) -> 0 | AW13: =ROUND((AM13-AO13-AV13-AU13),-3) -> 15442000 | AX13: 13055000 | AZ13: =ROUND(AW13-AX13+AY13,0) -> 2387000 | BA13: =AM13+AP13 -> 17141650 | BC13: =(U13-V13) -> 0 | BD13: =AF13 -> 0 | BE13: 0 | BF13: =T13 -> 1630000 | BG13: 12830000 | BH13: 0 | BI13: =AW13-BG13 -> 2612000 | BJ13: CL đi muộn | BK13: Trần Minh Tuyết | BL13: TRAN MINH TUYET | BM13: 0983280899 | BN13: QUAN DOI (MB)-311 | BO13: 0983280899 | BP13: QUAN DOI (MB)-311 | BQ13: Trần Minh Tuyết | BR13: GROSS | BS13: Trần Minh Tuyết | BW13: 14000000 | BX13: =L13-BW13 -> 2000000
A14: =A13+1 -> 6 | B14: Nguyễn Hữu Tuấn Minh | C14: tuanminh811.work@gmail.com | D14: Lập trình viên | F14: ON | L14: =L13-1000000 -> 15000000 | M14: =L14 -> 15000000 | N14: =VLOOKUP(B14,BHXH!$E$7:$F$20,2,0) -> 5310000 | O14: =M14-(N14+P14+Q14+R14+S14) -> 7810000 | P14: 250000 | Q14: 400000 | R14: 500000 | S14: 730000 | T14: =SUM(Q14:S14) -> 1630000 | U14: =SUM(W14:Y14) -> 22 | V14: 22 | Y14: =VLOOKUP(B14, 'Thưởng hiệu suất'!$B:$D,3,0) -> 22 | AA14: =SUM(AB14:AD14) -> 15000000 | AB14: =ROUND($G14/V14*W14,0) -> 0 | AC14: =ROUND(I14/V14*X14,0) -> 0 | AD14: =ROUND($M14/V14*Y14,0) -> 15000000 | AF14: =SUM(AG14:AL14) -> -450000 | AG14: =SUMIF('Tổng hợp OT'!B:B,B14,'Tổng hợp OT'!D:D) -> 0 | AJ14: =-VLOOKUP(B14,'Thưởng hiệu suất'!$B$3:$D$36,2,0) -> -450000 | AM14: =AA14+AF14 -> 14550000 | AN14: =VLOOKUP(B14,BHXH!$E$7:$F$17,2,0) -> 5310000 | AO14: =$AN14*10.5% -> 557550 | AP14: =$AN14*21.5% -> 1141650 | AQ14: 0 | AR14: =IF($E14=10%,0,(AQ14*6200000+15500000)) -> 15500000 | AS14: =AM14-(Q14+R14+S14)/V14*U14-AG14 -> 12920000 | AT14: =ROUND(IF((AS14-AR14-AO14)<0,0,(AS14-AR14-AO14)),0) -> 0 | AV14: =IF(AT14<=0,0,IF(AT14<=10000000,AT14*5%,IF(AT14<=30000000,AT14*10%-500000,IF(AT14<=60000000,AT14*20%-3500000,IF(AT14<=100000000,AT14*30%-9500000,AT14*35%-14500000))))) -> 0 | AW14: =ROUND((AM14-AO14-AV14-AU14),-3) -> 13992000 | AX14: 15992000 | AZ14: =ROUND(AW14-AX14+AY14,0) -> -2000000 | BA14: =AM14+AP14 -> 15691650 | BC14: =(U14-V14) -> 0 | BD14: =AF14 -> -450000 | BE14: 450500 | BF14: =T14 -> 1630000 | BG14: 16067000 | BH14: 0 | BI14: =AW14-BG14 -> -2075000 | BJ14: CL đi muộn | BK14: Nguyễn Hữu Tuấn Minh | BL14: NGUYEN HUU TUAN MINH | BM14: 081120026868 | BN14: VIET NAM THINH VUONG (VPBANK)-309 | BO14: 0081120026868 | BP14: QUAN DOI (MB)-311 | BQ14: Nguyễn Hữu Tuấn Minh | BR14: GROSS | BS14: Nguyễn Hữu Tuấn Minh | BT14: 15415000 | BU14: 1500000 | BV14: =AW14-BT14-BU14 -> -2923000 | BW14: 17000000 | BX14: =L14-BW14 -> -2000000
A15: NET | B15: Đỗ Khánh Huyền | C15: huyendk.bsmlabs@gmail.com | D15: Executive Assistant | F15: ON | L15: =L14-1000000 -> 14000000 | M15: =L15 -> 14000000 | N15: =VLOOKUP(B15,BHXH!$E$7:$F$20,2,0) -> 5310000 | O15: =M15-(N15+P15+Q15+R15+S15) -> 6810000 | P15: 250000 | Q15: 400000 | R15: 500000 | S15: 730000 | T15: =SUM(Q15:S15) -> 1630000 | U15: =SUM(W15:Y15) -> 22 | V15: 22 | Y15: =VLOOKUP(B15, 'Thưởng hiệu suất'!$B:$D,3,0) -> 22 | AA15: =SUM(AB15:AD15) -> 14000000 | AB15: =ROUND($G15/V15*W15,0) -> 0 | AC15: =ROUND(I15/V15*X15,0) -> 0 | AD15: =ROUND($M15/V15*Y15,0) -> 14000000 | AF15: =SUM(AG15:AL15) -> -50000 | AG15: =SUMIF('Tổng hợp OT'!B:B,B15,'Tổng hợp OT'!D:D) -> 0 | AJ15: =-VLOOKUP(B15,'Thưởng hiệu suất'!$B$3:$D$36,2,0) -> -50000 | AM15: =AA15+AF15 -> 13950000 | AN15: =VLOOKUP(B15,BHXH!$E$7:$F$17,2,0) -> 5310000 | AO15: =$AN15*10.5% -> 557550 | AP15: =$AN15*21.5% -> 1141650 | AQ15: 0 | AR15: =IF($E15=10%,0,(AQ15*6200000+15500000)) -> 15500000 | AS15: =AM15-(Q15+R15+S15)/V15*U15-AG15 -> 12320000 | AT15: =ROUND(IF((AS15-AR15-AO15)<0,0,(AS15-AR15-AO15)),0) -> 0 | AU15: 0 | AV15: =IF(AT15<=0,0,IF(AT15<=10000000,AT15*5%,IF(AT15<=30000000,AT15*10%-500000,IF(AT15<=60000000,AT15*20%-3500000,IF(AT15<=100000000,AT15*30%-9500000,AT15*35%-14500000))))) -> 0 | AW15: =ROUND((AM15-AO15-AV15-AU15),-3) -> 13392000 | AZ15: =ROUND(AW15-AX15+AY15,0) -> 13392000 | BA15: =AM15+AP15 -> 15091650 | BC15: =(U15-V15) -> 0 | BD15: =AF15 -> -50000 | BE15: 0 | BF15: =T15 -> 1630000 | BG15: 30000000 | BH15: 0 | BI15: =AW15-BG15 -> -16608000 | BK15: Đỗ Khánh Huyền | BL15: DO KHANH HUYEN | BM15: 477398871 | BN15: VIET NAM THINH VUONG (VPBANK)-309 | BO15: 019121870 | BP15: QUOC TE (VIB)-314 | BQ15: Đỗ Khánh Huyền | BR15: NET | BS15: Đỗ Khánh Huyền | BW15: 31431994 | BX15: =L15-BW15 -> -17431994
A16: 8 | B16: Nguyễn Tử Trường Lâm | C16: Lamntt.bsmlabs@gmail.com | D16: Video Editor | F16: ON | L16: =L15-1000000 -> 13000000 | M16: =L16 -> 13000000 | N16: =VLOOKUP(B16,BHXH!$E$7:$F$20,2,0) -> 5310000 | O16: =M16-(N16+P16+Q16+R16+S16) -> 5810000 | P16: 250000 | Q16: 400000 | R16: 500000 | S16: 730000 | T16: =SUM(Q16:S16) -> 1630000 | U16: =SUM(W16:Y16) -> 22 | V16: 22 | Y16: =VLOOKUP(B16, 'Thưởng hiệu suất'!$B:$D,3,0) -> 22 | AA16: =SUM(AB16:AD16) -> 13000000 | AB16: =ROUND($G16/V16*W16,0) -> 0 | AC16: =ROUND(I16/V16*X16,0) -> 0 | AD16: =ROUND($M16/V16*Y16,0) -> 13000000 | AF16: =SUM(AG16:AL16) -> 0 | AG16: =SUMIF('Tổng hợp OT'!B:B,B16,'Tổng hợp OT'!D:D) -> 0 | AJ16: =-VLOOKUP(B16,'Thưởng hiệu suất'!$B$3:$D$36,2,0) -> 0 | AM16: =AA16+AF16 -> 13000000 | AN16: =VLOOKUP(B16,BHXH!$E$7:$F$17,2,0) -> 5310000 | AO16: =$AN16*10.5% -> 557550 | AP16: =$AN16*21.5% -> 1141650 | AQ16: 0 | AR16: =IF($E16=10%,0,(AQ16*6200000+15500000)) -> 15500000 | AS16: =AM16-(Q16+R16+S16)/V16*U16-AG16 -> 11370000 | AT16: =ROUND(IF((AS16-AR16-AO16)<0,0,(AS16-AR16-AO16)),0) -> 0 | AU16: 0 | AV16: =IF(AT16<=0,0,IF(AT16<=10000000,AT16*5%,IF(AT16<=30000000,AT16*10%-500000,IF(AT16<=60000000,AT16*20%-3500000,IF(AT16<=100000000,AT16*30%-9500000,AT16*35%-14500000))))) -> 0 | AW16: =ROUND((AM16-AO16-AV16-AU16),-3) -> 12442000 | AX16: 16092000 | AY16: 150000 | AZ16: =ROUND(AW16-AX16+AY16,0) -> -3500000 | BA16: =AM16+AP16 -> 14141650 | BC16: =(U16-V16) -> 0 | BD16: =AF16 -> 0 | BE16: 1055000 | BF16: =T16 -> 1630000 | BG16: 14892000 | BH16: 0 | BI16: =AW16-BG16 -> -2450000 | BJ16: T2 thiếu 1 ngày công, đã BX | BK16: Nguyễn Tử Trường Lâm | BL16: NGUYEN TU TRUONG LAM | BM16: 104229093 | BN16: VIET NAM THINH VUONG (VPBANK)-309 | BO16: 104229093 | BP16: VIET NAM THINH VUONG (VPBANK)-309 | BQ16: Nguyễn Tử Trường Lâm | BR16: GROSS | BS16: Nguyễn Tử Trường Lâm | BW16: 16500000 | BX16: =L16-BW16 -> -3500000
A17: =A16+1 -> 9 | B17: Nguyễn Song Hà | C17: songha@bsmlabs.io | D17: Visual Art Director | F17: ON | L17: 12000000 | M17: =L17 -> 12000000 | N17: =VLOOKUP(B17,BHXH!$E$7:$F$20,2,0) -> 5310000 | O17: =M17-(N17+P17+Q17+R17+S17) -> 4060000 | P17: 500000 | Q17: 400000 | R17: 1000000 | S17: 730000 | T17: =SUM(Q17:S17) -> 2130000 | U17: =SUM(W17:Y17) -> 22 | V17: 22 | Y17: =VLOOKUP(B17, 'Thưởng hiệu suất'!$B:$D,3,0) -> 22 | AA17: =SUM(AB17:AD17) -> 12000000 | AB17: =ROUND($G17/V17*W17,0) -> 0 | AC17: =ROUND(I17/V17*X17,0) -> 0 | AD17: =ROUND($M17/V17*Y17,0) -> 12000000 | AF17: =SUM(AG17:AL17) -> 0 | AG17: =SUMIF('Tổng hợp OT'!B:B,B17,'Tổng hợp OT'!D:D) -> 0 | AJ17: =-VLOOKUP(B17,'Thưởng hiệu suất'!$B$3:$D$36,2,0) -> 0 | AM17: =AA17+AF17 -> 12000000 | AN17: =VLOOKUP(B17,BHXH!$E$7:$F$17,2,0) -> 5310000 | AO17: =$AN17*10.5% -> 557550 | AP17: =$AN17*21.5% -> 1141650 | AQ17: 0 | AR17: =IF($E17=10%,0,(AQ17*6200000+15500000)) -> 15500000 | AS17: =AM17-(Q17+R17+S17)/V17*U17-AG17 -> 9870000 | AT17: =ROUND(IF((AS17-AR17-AO17)<0,0,(AS17-AR17-AO17)),0) -> 0 | AU17: 0 | AV17: =IF(AT17<=0,0,IF(AT17<=10000000,AT17*5%,IF(AT17<=30000000,AT17*10%-500000,IF(AT17<=60000000,AT17*20%-3500000,IF(AT17<=100000000,AT17*30%-9500000,AT17*35%-14500000))))) -> 0 | AW17: =ROUND((AM17-AO17-AV17-AU17),-3) -> 11442000 | AX17: 43713000 | AZ17: =ROUND(AW17-AX17+AY17,0) -> -32271000 | BA17: =AM17+AP17 -> 13141650 | BC17: =(U17-V17) -> 0 | BD17: =AF17 -> 0 | BE17: 0 | BF17: =T17 -> 2130000 | BG17: 43713000 | BH17: 0 | BI17: =AW17-BG17 -> -32271000 | BK17: Nguyễn Song Hà | BL17: NGUYEN SONG HA | BM17: 477370012 | BN17: VIET NAM THINH VUONG (VPBANK)-309 | BO17: 19020074352016 | BP17: TCB | BQ17: Nguyễn Song Hà | BR17: GROSS | BS17: Nguyễn Song Hà | BW17: 47000000 | BX17: =L17-BW17 -> -35000000
A18: NET | B18: Phạm Đăng Bình | C18: binhpham.bsmlabs@gmail.com | D18: Video Editor | F18: ON | L18: 12000000 | M18: =L18 -> 12000000 | N18: =VLOOKUP(B18,BHXH!$E$7:$F$20,2,0) -> 5310000 | O18: =M18-(N18+P18+Q18+R18+S18) -> 4810000 | P18: 250000 | Q18: 400000 | R18: 500000 | S18: 730000 | T18: =SUM(Q18:S18) -> 1630000 | U18: =SUM(W18:Y18) -> 22 | V18: 22 | Y18: =VLOOKUP(B18, 'Thưởng hiệu suất'!$B:$D,3,0) -> 22 | AA18: =SUM(AB18:AD18) -> 12000000 | AB18: =ROUND($G18/V18*W18,0) -> 0 | AC18: =ROUND(I18/V18*X18,0) -> 0 | AD18: =ROUND($M18/V18*Y18,0) -> 12000000 | AF18: =SUM(AG18:AL18) -> 0 | AG18: =SUMIF('Tổng hợp OT'!B:B,B18,'Tổng hợp OT'!D:D) -> 0 | AJ18: =-VLOOKUP(B18,'Thưởng hiệu suất'!$B$3:$D$36,2,0) -> 0 | AM18: =AA18+AF18 -> 12000000 | AN18: =VLOOKUP(B18,BHXH!$E$7:$F$17,2,0) -> 5310000 | AO18: =$AN18*10.5% -> 557550 | AP18: =$AN18*21.5% -> 1141650 | AQ18: 1 | AR18: =IF($E18=10%,0,(AQ18*6200000+15500000)) -> 21700000 | AS18: =AM18-(Q18+R18+S18)/V18*U18-AG18 -> 10370000 | AT18: =ROUND(IF((AS18-AR18-AO18)<0,0,(AS18-AR18-AO18)),0) -> 0 | AU18: 0 | AV18: =IF(AT18<=0,0,IF(AT18<=10000000,AT18*5%,IF(AT18<=30000000,AT18*10%-500000,IF(AT18<=60000000,AT18*20%-3500000,IF(AT18<=100000000,AT18*30%-9500000,AT18*35%-14500000))))) -> 0 | AW18: =ROUND((AM18-AO18-AV18-AU18),-3) -> 11442000 | AX18: 17000000 | AZ18: =ROUND(AW18-AX18+AY18,0) -> -5558000 | BA18: =AM18+AP18 -> 13141650 | BC18: =(U18-V18) -> 0 | BD18: =AF18 -> 0 | BE18: -75000 | BF18: =T18 -> 1630000 | BG18: 17000000 | BH18: 0 | BI18: =AW18-BG18 -> -5558000 | BK18: Phạm Đăng Bình | BL18: PHAM DANG BINH | BM18: 19027455280016 | BN18: TCB | BO18: 19027455280016 | BP18: TCB | BQ18: Phạm Đăng Bình | BR18: NET | BS18: Phạm Đăng Bình | BW18: 17557550 | BX18: =L18-BW18 -> -5557550
A19: 11 | B19: Nguyễn Thị Kim Phượng | C19: phuong.nguyen@bsmlabs.io | D19: L&D Business Partner | F19: ON | L19: 12000000 | M19: =L19 -> 12000000 | N19: =VLOOKUP(B19,BHXH!$E$7:$F$20,2,0) -> 5310000 | O19: =M19-(N19+P19+Q19+R19+S19) -> 4810000 | P19: 250000 | Q19: 400000 | R19: 500000 | S19: 730000 | T19: =SUM(Q19:S19) -> 1630000 | U19: =SUM(W19:Y19) -> 22 | V19: 22 | Y19: =VLOOKUP(B19, 'Thưởng hiệu suất'!$B:$D,3,0) -> 22 | AA19: =SUM(AB19:AD19) -> 12000000 | AB19: =ROUND($G19/V19*W19,0) -> 0 | AC19: =ROUND(I19/V19*X19,0) -> 0 | AD19: =ROUND($M19/V19*Y19,0) -> 12000000 | AF19: =SUM(AG19:AL19) -> 0 | AG19: =SUMIF('Tổng hợp OT'!B:B,B19,'Tổng hợp OT'!D:D) -> 0 | AJ19: =-VLOOKUP(B19,'Thưởng hiệu suất'!$B$3:$D$36,2,0) -> 0 | AM19: =AA19+AF19 -> 12000000 | AN19: =VLOOKUP(B19,BHXH!$E$7:$F$17,2,0) -> 5310000 | AO19: =$AN19*10.5% -> 557550 | AP19: =$AN19*21.5% -> 1141650 | AQ19: 1 | AR19: =IF($E19=10%,0,(AQ19*6200000+15500000)) -> 21700000 | AS19: =AM19-(Q19+R19+S19)/V19*U19-AG19 -> 10370000 | AT19: =ROUND(IF((AS19-AR19-AO19)<0,0,(AS19-AR19-AO19)),0) -> 0 | AU19: 0 | AV19: =IF(AT19<=0,0,IF(AT19<=10000000,AT19*5%,IF(AT19<=30000000,AT19*10%-500000,IF(AT19<=60000000,AT19*20%-3500000,IF(AT19<=100000000,AT19*30%-9500000,AT19*35%-14500000))))) -> 0 | AW19: =ROUND((AM19-AO19-AV19-AU19),-3) -> 11442000 | AX19: 33483000 | AZ19: =ROUND(AW19-AX19+AY19,0) -> -22041000 | BA19: =AM19+AP19 -> 13141650 | BC19: =(U19-V19) -> 0 | BD19: =AF19 -> 0 | BE19: 0 | BF19: =T19 -> 1630000 | BG19: 40514000 | BH19: 0 | BI19: =AW19-BG19 -> -29072000 | BJ19: Tăng lương | BK19: Nguyễn Thị Kim Phượng | BL19: NGUYEN THI KIM PHUONG | BM19: 19033966641017 | BN19: TCB | BO19: 19033966641017 | BP19: TCB | BQ19: Nguyễn Thị Kim Phượng | BR19: GROSS | BS19: Nguyễn Thị Kim Phượng | BW19: 27500000 | BX19: =L19-BW19 -> -15500000
